Workbook
Name Slicer_Channel: #N/A
Name Slicer_Country: #N/A
Name Slicer_OrderDate__________mmm_yyyy: #N/A
Name Slicer_ProductCategory: #N/A
Name Slicer_Region: #N/A
Name Slicer_Salesperson: #N/A

Sheet Data
A1: OrderID | B1: OrderDate | C1: RequiredDate | D1: Region | E1: Country | F1: City | G1: CustomerSegment | H1: Channel | I1: Salesperson | J1: ProductCategory | K1: SKU | L1: UnitCost | M1: UnitPrice | N1: DiscountPct | O1: Quantity
A2: ORD-2024-275203 | B2: 45362 | C2: 45388 | D2: Africa | E2: Kenya | F2: Kisumu | G2: Corporate | H2: Retail | I2: C. Otieno | J2: Components | K2: CMP-8270 | L2: 279.24 | M2: 608.9 | N2: 0.112 | O2: 9
A3: ORD-2024-358795 | B3: 45588 | C3: 45587 | D3: Africa | E3: Nigeria | F3: Port Harcourt | G3: Education | H3: Online | I3: J. Njeri | J3: Printers | K3: PRN-9322 | L3: 1084.39 | M3: 759.33 | N3: 0.237 | O3: 31
A4: ORD-2023-373538 | B4: 44985 | C4: 45010 | D4: Africa | E4: Kenya | F4: Nairobi | G4: Corporate | H4: Retail | I4: I. Johnson | J4: Networking | K4: NET-9666 | L4: 1460.76 | M4: -30.66 | N4: 0.131 | O4: 12
A5: ORD-2025-168148 | B5: 45745 | C5: 45749 | D5: Africa | E5: Nigeria | F5: Lagos | G5: Non-Profit | H5: Marketplace | I5: G. Dubois | J5: Phones | K5: PHN-4556 | L5: 259.93 | M5: 255.94 | N5: 0.072 | O5: 22
A6: ORD-2023-824839 | B6: 45266 | C6: 45291 | D6: Asia | E6: Japan | F6: Osaka | G6: Consumer | H6: Retail | I6: L. Okafor | J6: Printers | K6: PRN-8041 | L6: 663.03 | M6: 813.51 | N6: 0.102 | O6: 15
A7: ORD-2023-723587 | B7: 44928 | C7: 44931 | D7: Americas | E7: Canada | F7: Toronto | G7: Corporate | H7: Distributor | I7: B. Chen | J7: Laptops | K7: LAP-8555 | L7: 315.87 | M7: 591.68 | N7: 0 | O7: 7
A8: ORD-2024-336584 | B8: 45653 | C8: 45671 | D8: Asia | E8: India | F8: Bengaluru | G8: Small Business | H8: Marketplace | I8: E. Garcia | J8: Monitors | K8: MON-8629 | L8: 586.07 | M8: 845.97 | N8: 0.147 | O8: 4
A9: ORD-2023-112666 | B9: 44941 | C9: 44939 | D9: Africa | E9: Nigeria | F9: Abuja | G9: Education | H9: Online | I9: O. Wang | J9: Printers | K9: PRN-6276 | L9: 28.38 | M9: 47.22 | N9: 0.194 | O9: 18
A10: ORD-2024-589570 | B10: 45416 | C10: 45441 | D10: Africa | E10: Nigeria | F10: Abuja | G10: Non-Profit | H10: Marketplace | I10: O. Wang | J10: Monitors | K10: MON-6892 | L10: 1295.34 | M10: 2530.81 | N10: 0.031 | O10: 6
A11: ORD-2025-997421 | B11: 45798 | C11: 45817 | D11: Americas | E11: Brazil | F11: São Paulo | G11: Non-Profit | H11: Online | I11: A. Patel | J11: Components | K11: CMP-3731 | L11: 1331.38 | M11: 2309.56 | N11: 0.149 | O11: 31
A12: ORD-2024-210687 | B12: 45319 | C12: 45331 | D12: Europe | E12: Germany | F12: Berlin | G12: Corporate | H12: Online | I12: G. Dubois | J12: Accessories | K12: ACC-7938 | L12: 644.17 | M12: 700.12 | N12: 0.006 | O12: 23
A13: ORD-2025-515515 | B13: 45660 | C13: 45680 | D13: Asia | E13: Japan | F13: Osaka | G13: Corporate | H13: Distributor | I13: F. Müller | J13: Phones | K13: PHN-7019 | L13: 908.6 | M13: 691.37 | N13: 0.25 | O13: 20
... A34: ORD-2025-474710 | B34: 45862 | C34: 45875 | D34: Africa | E34: South Africa | F34: Johannesburg | G34: Education | H34: Marketplace | I34: D. Smith | J34: Networking | K34: NET-7966 | L34: 1463.9 | M34: 2633.02 | N34: 0.084 | O34: 4
A35: ORD-2024-629525 | B35: 45400 | C35: 45420 | D35: Europe | E35: United Kingdom | F35: London | G35: Non-Profit | I35: D. Smith | J35: Laptops | K35: LAP-9932 | L35: 645.33 | M35: 1321.85 | N35: 0 | O35: 10
A36: ORD-2024-167215 | B36: 45527 | C36: 45525 | D36: Africa | E36: South Africa | F36: Johannesburg | G36: Education | H36: Retail | I36: E. Garcia | J36: Components | K36: CMP-1559 | L36: 1432.52 | M36: 3036.87 | N36: 0 | O36: 9
A37: ORD-2023-864121 | B37: 45012 | C37: 45038 | D37: Asia | E37: India | F37: Delhi | G37: Non-Profit | H37: Marketplace | I37: J. Njeri | J37: Printers | K37: PRN-4506 | L37: 178.53 | M37: 199.37 | N37: 0.101 | O37: 37
A38: ORD-2024-692673 | B38: 45358 | C38: 45376 | D38: Europe | E38: Germany | F38: Munich | G38: Corporate | H38: Online | I38: B. Chen | J38: Components | K38: CMP-7617 | L38: 712.84 | M38: 927.51 | N38: 0.243 | O38: 27
A39: ORD-2025-718992 | B39: 45832 | C39: 45848 | D39: Asia | E39: China | F39: Shanghai | G39: Enterprise | H39: Direct | I39: N. Brown | J39: Components | K39: CMP-8390 | L39: 757.19 | M39: 1735.41 | N39: 0.136 | O39: 8
A40: ORD-2024-599522 | B40: 45401 | C40: 45418 | D40: Africa | E40: Nigeria | F40: Port Harcourt | G40: Non-Profit | H40: Online | I40: A. Patel | J40: Printers | K40: PRN-7303 | L40: 865.33 | M40: 1395.64 | N40: 0.175 | O40: 13
A41: ORD-2023-651638 | B41: 45094 | C41: 45101 | D41: Americas | E41: USA | F41: San Francisco | G41: Corporate | H41: Retail | I41: I. Johnson | J41: Printers | K41: PRN-6536 | L41: 313.99 | M41: 454.42 | N41: 0.129 | O41: 9
A42: ORD-2024-635626 | B42: 45531 | C42: 45554 | D42: Europe | E42: Germany | F42: Berlin | G42: Small Business | H42: Direct | I42: D. Smith | J42: Monitors | K42: MON-9967 | L42: 1024.01 | M42: 1580.97 | N42: 0.037 | O42: 27
A43: ORD-2024-296582 | B43: 45302 | C43: 45324 | D43: Africa | E43: South Africa | F43: Durban | G43: Consumer | H43: Online | I43: K. Singh | J43: Networking | K43: NET-1412 | L43: 1206.2 | M43: 1759.79 | N43: 0 | O43: 6
A44: ORD-2024-998320 | B44: 45590 | C44: 45610 | D44: Africa | E44: Kenya | F44: Mombasa | G44: Corporate | H44: Direct | I44: H. Kim | J44: Printers | K44: PRN-3143 | L44: 1396.48 | M44: 3204.5 | N44: 0.318 | O44: 14
A45: ORD-2025-820255 | B45: 45806 | C45: 45828 | D45: Europe | E45: Germany | F45: Berlin | G45: Corporate | H45: Direct | I45: A. Patel | J45: Printers | K45: PRN-9787 | L45: 483.47 | M45: 1135.43 | N45: 0.146 | O45: 11
A46: ORD-2024-389336 | B46: 45432 | C46: 45445 | D46: Americas | E46: Canada | F46: Vancouver | G46: Enterprise | H46: Marketplace | I46: K. Singh | J46: Components | K46: CMP-5946 | L46: 675.43 | M46: 996.36 | N46: 0.182 | O46: 22
A47: ORD-2023-308124 | B47: 45035 | C47: 45046 | D47: Asia | E47: India | F47: Delhi | G47: Small Business | H47: Retail | I47: A. Patel | J47: Networking | K47: NET-2062 | L47: 826.55 | M47: 1397.05 | N47: 0.169 | O47: 28
... A77: ORD-2023-722117 | B77: 45187 | C77: 45207 | D77: Asia | E77: India | F77: Delhi | G77: Small Business | H77: Direct | I77: B. Chen | J77: Components | K77: CMP-1009 | L77: 825.64 | M77: 1108.43 | N77: 0.114 | O77: 7
A78: ORD-2024-446699 | B78: 45532 | C78: 45560 | D78: Americas | E78: Brazil | F78: Rio de Janeiro | G78: Non-Profit | H78: Online | J78: Accessories | K78: ACC-4490 | L78: 1394.65 | M78: 3144.1 | N78: 0.134 | O78: 13
A79: ORD-2024-451005 | B79: 45473 | C79: 45471 | D79: Americas | E79: Brazil | F79: Rio de Janeiro | G79: Small Business | H79: Direct | I79: L. Okafor | J79: Accessories | K79: ACC-9162 | L79: 1112.98 | M79: 2095.73 | N79: 0.072 | O79: 17
A80: ORD-2023-290279 | B80: 45091 | C80: 45093 | D80: Europe | E80: United Kingdom | F80: Manchester | G80: Non-Profit | H80: Direct | I80: K. Singh | J80: Components | K80: CMP-5820 | L80: 357.36 | M80: 703.62 | N80: 0.257 | O80: 20
A81: ORD-2024-192263 | B81: 45617 | C81: 45647 | D81: Europe | E81: France | F81: Marseille | G81: Small Business | H81: Direct | I81: I. Johnson | J81: Monitors | K81: MON-7943 | L81: 1122.68 | M81: 1997.19 | N81: 0.186 | O81: 3
A82: ORD-2023-159379 | B82: 44965 | C82: 44968 | D82: Africa | E82: South Africa | F82: Cape Town | G82: Corporate | H82: Direct | I82: M. Rossi | J82: Networking | K82: NET-5018 | L82: 1410.05 | M82: 2763.95 | N82: 0.161 | O82: 26
A83: ORD-2023-343322 | B83: 45157 | C83: 45181 | D83: Americas | E83: Canada | F83: Vancouver | G83: Enterprise | H83: Retail | I83: I. Johnson | J83: Printers | K83: PRN-9669 | L83: 1183.95 | M83: 1503.53 | N83: 0.241 | O83: 16
A84: ORD-2025-114382 | B84: 45791 | C84: 45801 | D84: Europe | E84: France | F84: Paris | G84: Small Business | H84: Marketplace | I84: K. Singh | J84: Components | K84: CMP-2865 | L84: 170.39 | M84: 388.04 | N84: 0.084 | O84: 15
A85: ORD-2025-488349 | B85: 45770 | C85: 45769 | D85: Americas | E85: USA | F85: San Francisco | G85: Non-Profit | H85: Distributor | I85: D. Smith | J85: Monitors | K85: MON-3371 | L85: 23.24 | M85: 44.57 | N85: 0.215 | O85: 15
A86: ORD-2025-330203 | B86: 45741 | C86: 45764 | D86: Europe | E86: United Kingdom | F86: London | G86: Consumer | H86: Retail | I86: H. Kim | J86: Networking | K86: NET-7166 | L86: 1421.19 | M86: 1808.26 | N86: 0.104 | O86: 13
A87: ORD-2023-841426 | B87: 45282 | C87: 45283 | D87: Africa | E87: South Africa | F87: Cape Town | G87: Non-Profit | H87: Marketplace | I87: D. Smith | J87: Components | K87: CMP-4531 | L87: 1186.18 | M87: 1285.09 | N87: 0.07 | O87: 11
A88: ORD-2024-594592 | B88: 45388 | C88: 45407 | D88: Asia | E88: China | F88: Shanghai | G88: Corporate | H88: Retail | I88: K. Singh | J88: Components | K88: CMP-8196 | L88: 1366.48 | M88: 1678.14 | N88: 0.154 | O88: 10
A89: ORD-2025-863978 | B89: 45876 | C89: 45888 | D89: Africa | E89: Kenya | F89: Nakuru | G89: Corporate | I89: M. Rossi | J89: Components | K89: CMP-2854 | L89: 601.51 | M89: 679.35 | N89: 0.188 | O89: 3
...

Sheet Clean
A1: Column1 | B1: OrderDate | C1: OrderDate (mmm-yyyy) | D1: Order Quarter | E1: RequiredDate | F1: Cleaned RequiredDate | G1: LeadTimeDays | H1: Cleaned LeadTimeDays | I1: Target Met (7 days) | J1: StartDate | K1: Region | L1: Country | M1: City | N1: Region hierarchy | O1: CustomerSegment | P1: Channel | Q1: Salesperson | R1: ProductCategory | S1: SKU | T1: UnitCost | U1: UnitPrice | V1: Cleaned UnitPrice | W1: PriceBand | X1: DiscountPct | Y1: Cleaned DiscountPct | Z1: Discount(>20%) | AA1: Quantity | AB1: GrossRevenue | AC1: CostOfGoods | AD1: GrossProfit | AE1: MarginPct | AF1: DiscountPct (Scenario) | AG1: Quantity (Scenario) | AH1: UnitCost (Scenario) | AI1: GrossRevenue (Scenario) | AJ1: GrossProfit(Scenario)
A2: ORD-2024-275203 | B2: 45362 | C2: 45362 | D2: ="Q"&ROUNDUP(MONTH(B2)/3,0)&"-"&YEAR(B2) -> Q1-2024 | E2: 45388 | F2: 45388 | G2: =E2-B2 -> 26 | H2: =F2-B2 -> 26 | I2: =IF(H2<=7, "Yes", "No") -> No | J2: =_xlfn.MINIFS($B$2:$B$633, $L$2:$L$633, L2) -> 44946 | K2: Africa | L2: Kenya | M2: Kisumu | N2: =_xlfn.TEXTJOIN(" - ", TRUE, K2:M2) -> Africa - Kenya - Kisumu | O2: Corporate | P2: Retail | Q2: C. Otieno | R2: Components | S2: CMP-8270 | T2: 279.24 | U2: 608.9 | V2: =ABS(U2) -> 608.9 | W2: =IF(V2 <= _xlfn.PERCENTILE.INC($V$2:$V$633, 0.33), "Low", IF(V2 <= _xlfn.PERCENTILE.INC($V$2:$V$633, 0.67), "Medium", "High")) -> Low | X2: 0.112 | Y2: =IF(X2>30%,AVERAGEIF($X$2:$X$633,"<30%"),X2) -> 0.112 | Z2: =IF(Y2>0.2, "Yes", "No") -> No | AA2: 9 | AB2: =U2*AA2*(1-Y2) -> 4866.3288 | AC2: =T2*AA2 -> 2513.16 | AD2: =AB2-AC2 -> 2353.1688 | AE2: =IF(AB2=0, 0, AD2 / AB2) -> 0.48356141 | AF2: =MIN(Y2,'Scenario Modeling'!$B$2) -> 0.112 | AG2: =ROUND(AA2 * (1 + 'Scenario Modeling'!$B$4), 0) -> 9 | AH2: =T2 * (1 + 'Scenario Modeling'!$B$3) -> 279.24 | AI2: =V2 * AG2 * (1 - AF2) -> 4866.3288 | AJ2: =AI2 - (AH2 * AG2) -> 2353.1688
A3: ORD-2024-358795 | B3: 45588 | C3: 45588 | D3: ="Q"&ROUNDUP(MONTH(B3)/3,0)&"-"&YEAR(B3) -> Q4-2024 | E3: 45587 | F3: =B3+10 -> 45598 | G3: =E3-B3 -> -1 | H3: =F3-B3 -> 10 | I3: =IF(H3<=7, "Yes", "No") -> No | J3: =_xlfn.MINIFS($B$2:$B$633, $L$2:$L$633, L3) -> 44941 | K3: Africa | L3: Nigeria | M3: Port Harcourt | N3: =_xlfn.TEXTJOIN(" - ", TRUE, K3:M3) -> Africa - Nigeria - Port Harcourt | O3: Education | P3: Online | Q3: J. Njeri | R3: Printers | S3: PRN-9322 | T3: 1084.39 | U3: 759.33 | V3: =ABS(U3) -> 759.33 | W3: =IF(V3 <= _xlfn.PERCENTILE.INC($V$2:$V$633, 0.33), "Low", IF(V3 <= _xlfn.PERCENTILE.INC($V$2:$V$633, 0.67), "Medium", "High")) -> Low | X3: 0.237 | Y3: =IF(X3>30%,AVERAGEIF($X$2:$X$633,"<30%"),X3) -> 0.237 | Z3: =IF(Y3>0.2, "Yes", "No") -> Yes | AA3: 31 | AB3: =U3*AA3*(1-Y3) -> 17960.432 | AC3: =T3*AA3 -> 33616.09 | AD3: =AB3-AC3 -> -15655.658 | AE3: =IF(AB3=0, 0, AD3 / AB3) -> -0.87167486 | AF3: =MIN(Y3,'Scenario Modeling'!$B$2) -> 0.237 | AG3: =ROUND(AA3 * (1 + 'Scenario Modeling'!$B$4), 0) -> 31 | AH3: =T3 * (1 + 'Scenario Modeling'!$B$3) -> 1084.39 | AI3: =V3 * AG3 * (1 - AF3) -> 17960.432 | AJ3: =AI3 - (AH3 * AG3) -> -15655.658
A4: ORD-2023-373538 | B4: 44985 | C4: 44985 | D4: ="Q"&ROUNDUP(MONTH(B4)/3,0)&"-"&YEAR(B4) -> Q1-2023 | E4: 45010 | F4: 45010 | G4: =E4-B4 -> 25 | H4: =F4-B4 -> 25 | I4: =IF(H4<=7, "Yes", "No") -> No | J4: =_xlfn.MINIFS($B$2:$B$633, $L$2:$L$633, L4) -> 44946 | K4: Africa | L4: Kenya | M4: Nairobi | N4: =_xlfn.TEXTJOIN(" - ", TRUE, K4:M4) -> Africa - Kenya - Nairobi | O4: Corporate | P4: Retail | Q4: I. Johnson | R4: Networking | S4: NET-9666 | T4: 1460.76 | U4: -30.66 | V4: =ABS(U4) -> 30.66 | W4: =IF(V4 <= _xlfn.PERCENTILE.INC($V$2:$V$633, 0.33), "Low", IF(V4 <= _xlfn.PERCENTILE.INC($V$2:$V$633, 0.67), "Medium", "High")) -> Low | X4: 0.131 | Y4: =IF(X4>30%,AVERAGEIF($X$2:$X$633,"<30%"),X4) -> 0.131 | Z4: =IF(Y4>0.2, "Yes", "No") -> No | AA4: 12 | AB4: =U4*AA4*(1-Y4) -> -319.72248 | AC4: =T4*AA4 -> 17529.12 | AD4: =AB4-AC4 -> -17848.842 | AE4: =IF(AB4=0, 0, AD4 / AB4) -> 55.826048 | AF4: =MIN(Y4,'Scenario Modeling'!$B$2) -> 0.131 | AG4: =ROUND(AA4 * (1 + 'Scenario Modeling'!$B$4), 0) -> 12 | AH4: =T4 * (1 + 'Scenario Modeling'!$B$3) -> 1460.76 | AI4: =V4 * AG4 * (1 - AF4) -> 319.72248 | AJ4: =AI4 - (AH4 * AG4) -> -17209.398
A5: ORD-2025-168148 | B5: 45745 | C5: 45745 | D5: ="Q"&ROUNDUP(MONTH(B5)/3,0)&"-"&YEAR(B5) -> Q1-2025 | E5: 45749 | F5: 45749 | G5: =E5-B5 -> 4 | H5: =F5-B5 -> 4 | I5: =IF(H5<=7, "Yes", "No") -> Yes | J5: =_xlfn.MINIFS($B$2:$B$633, $L$2:$L$633, L5) -> 44941 | K5: Africa | L5: Nigeria | M5: Lagos | N5: =_xlfn.TEXTJOIN(" - ", TRUE, K5:M5) -> Africa - Nigeria - Lagos | O5: Non-Profit | P5: Marketplace | Q5: G. Dubois | R5: Phones | S5: PHN-4556 | T5: 259.93 | U5: 255.94 | V5: =ABS(U5) -> 255.94 | W5: =IF(V5 <= _xlfn.PERCENTILE.INC($V$2:$V$633, 0.33), "Low", IF(V5 <= _xlfn.PERCENTILE.INC($V$2:$V$633, 0.67), "Medium", "High")) -> Low | X5: 0.072 | Y5: =IF(X5>30%,AVERAGEIF($X$2:$X$633,"<30%"),X5) -> 0.072 | Z5: =IF(Y5>0.2, "Yes", "No") -> No | AA5: 22 | AB5: =U5*AA5*(1-Y5) -> 5225.271 | AC5: =T5*AA5 -> 5718.46 | AD5: =AB5-AC5 -> -493.18896 | AE5: =IF(AB5=0, 0, AD5 / AB5) -> -0.094385335 | AF5: =MIN(Y5,'Scenario Modeling'!$B$2) -> 0.072 | AG5: =ROUND(AA5 * (1 + 'Scenario Modeling'!$B$4), 0) -> 22 | AH5: =T5 * (1 + 'Scenario Modeling'!$B$3) -> 259.93 | AI5: =V5 * AG5 * (1 - AF5) -> 5225.271 | AJ5: =AI5 - (AH5 * AG5) -> -493.18896
A6: ORD-2023-824839 | B6: 45266 | C6: 45266 | D6: ="Q"&ROUNDUP(MONTH(B6)/3,0)&"-"&YEAR(B6) -> Q4-2023 | E6: 45291 | F6: 45291 | G6: =E6-B6 -> 25 | H6: =F6-B6 -> 25 | I6: =IF(H6<=7, "Yes", "No") -> No | J6: =_xlfn.MINIFS($B$2:$B$633, $L$2:$L$633, L6) -> 44988 | K6: Asia | L6: Japan | M6: Osaka | N6: =_xlfn.TEXTJOIN(" - ", TRUE, K6:M6) -> Asia - Japan - Osaka | O6: Consumer | P6: Retail | Q6: L. Okafor | R6: Printers | S6: PRN-8041 | T6: 663.03 | U6: 813.51 | V6: =ABS(U6) -> 813.51 | W6: =IF(V6 <= _xlfn.PERCENTILE.INC($V$2:$V$633, 0.33), "Low", IF(V6 <= _xlfn.PERCENTILE.INC($V$2:$V$633, 0.67), "Medium", "High")) -> Low | X6: 0.102 | Y6: =IF(X6>30%,AVERAGEIF($X$2:$X$633,"<30%"),X6) -> 0.102 | Z6: =IF(Y6>0.2, "Yes", "No") -> No | AA6: 15 | AB6: =U6*AA6*(1-Y6) -> 10957.98 | AC6: =T6*AA6 -> 9945.45 | AD6: =AB6-AC6 -> 1012.5297 | AE6: =IF(AB6=0, 0, AD6 / AB6) -> 0.092401129 | AF6: =MIN(Y6,'Scenario Modeling'!$B$2) -> 0.102 | AG6: =ROUND(AA6 * (1 + 'Scenario Modeling'!$B$4), 0) -> 15 | AH6: =T6 * (1 + 'Scenario Modeling'!$B$3) -> 663.03 | AI6: =V6 * AG6 * (1 - AF6) -> 10957.98 | AJ6: =AI6 - (AH6 * AG6) -> 1012.5297
A7: ORD-2023-723587 | B7: 44928 | C7: 44928 | D7: ="Q"&ROUNDUP(MONTH(B7)/3,0)&"-"&YEAR(B7) -> Q1-2023 | E7: 44931 | F7: 44931 | G7: =E7-B7 -> 3 | H7: =F7-B7 -> 3 | I7: =IF(H7<=7, "Yes", "No") -> Yes | J7: =_xlfn.MINIFS($B$2:$B$633, $L$2:$L$633, L7) -> 44928 | K7: Americas | L7: Canada | M7: Toronto | N7: =_xlfn.TEXTJOIN(" - ", TRUE, K7:M7) -> Americas - Canada - Toronto | O7: Corporate | P7: Distributor | Q7: B. Chen | R7: Laptops | S7: LAP-8555 | T7: 315.87 | U7: 591.68 | V7: =ABS(U7) -> 591.68 | W7: =IF(V7 <= _xlfn.PERCENTILE.INC($V$2:$V$633, 0.33), "Low", IF(V7 <= _xlfn.PERCENTILE.INC($V$2:$V$633, 0.67), "Medium", "High")) -> Low | X7: 0 | Y7: =IF(X7>30%,AVERAGEIF($X$2:$X$633,"<30%"),X7) -> 0 | Z7: =IF(Y7>0.2, "Yes", "No") -> No | AA7: 7 | AB7: =U7*AA7*(1-Y7) -> 4141.76 | AC7: =T7*AA7 -> 2211.09 | AD7: =AB7-AC7 -> 1930.67 | AE7: =IF(AB7=0, 0, AD7 / AB7) -> 0.46614724 | AF7: =MIN(Y7,'Scenario Modeling'!$B$2) -> 0 | AG7: =ROUND(AA7 * (1 + 'Scenario Modeling'!$B$4), 0) -> 7 | AH7: =T7 * (1 + 'Scenario Modeling'!$B$3) -> 315.87 | AI7: =V7 * AG7 * (1 - AF7) -> 4141.76 | AJ7: =AI7 - (AH7 * AG7) -> 1930.67
A8: ORD-2024-336584 | B8: 45653 | C8: 45653 | D8: ="Q"&ROUNDUP(MONTH(B8)/3,0)&"-"&YEAR(B8) -> Q4-2024 | E8: 45671 | F8: 45671 | G8: =E8-B8 -> 18 | H8: =F8-B8 -> 18 | I8: =IF(H8<=7, "Yes", "No") -> No | J8: =_xlfn.MINIFS($B$2:$B$633, $L$2:$L$633, L8) -> 44955 | K8: Asia | L8: India | M8: Bengaluru | N8: =_xlfn.TEXTJOIN(" - ", TRUE, K8:M8) -> Asia - India - Bengaluru | O8: Small Business | P8: Marketplace | Q8: E. Garcia | R8: Monitors | S8: MON-8629 | T8: 586.07 | U8: 845.97 | V8: =ABS(U8) -> 845.97 | W8: =IF(V8 <= _xlfn.PERCENTILE.INC($V$2:$V$633, 0.33), "Low", IF(V8 <= _xlfn.PERCENTILE.INC($V$2:$V$633, 0.67), "Medium", "High")) -> Medium | X8: 0.147 | Y8: =IF(X8>30%,AVERAGEIF($X$2:$X$633,"<30%"),X8) -> 0.147 | Z8: =IF(Y8>0.2, "Yes", "No") -> No | AA8: 4 | AB8: =U8*AA8*(1-Y8) -> 2886.4496 | AC8: =T8*AA8 -> 2344.28 | AD8: =AB8-AC8 -> 542.16964 | AE8: =IF(AB8=0, 0, AD8 / AB8) -> 0.1878327 | AF8: =MIN(Y8,'Scenario Modeling'!$B$2) -> 0.147 | AG8: =ROUND(AA8 * (1 + 'Scenario Modeling'!$B$4), 0) -> 4 | AH8: =T8 * (1 + 'Scenario Modeling'!$B$3) -> 586.07 | AI8: =V8 * AG8 * (1 - AF8) -> 2886.4496 | AJ8: =AI8 - (AH8 * AG8) -> 542.16964
A9: ORD-2023-112666 | B9: 44941 | C9: 44941 | D9: ="Q"&ROUNDUP(MONTH(B9)/3,0)&"-"&YEAR(B9) -> Q1-2023 | E9: 44939 | F9: =B9+3 -> 44944 | G9: =E9-B9 -> -2 | H9: =F9-B9 -> 3 | I9: =IF(H9<=7, "Yes", "No") -> Yes | J9: =_xlfn.MINIFS($B$2:$B$633, $L$2:$L$633, L9) -> 44941 | K9: Africa | L9: Nigeria | M9: Abuja | N9: =_xlfn.TEXTJOIN(" - ", TRUE, K9:M9) -> Africa - Nigeria - Abuja | O9: Education | P9: Online | Q9: O. Wang | R9: Printers | S9: PRN-6276 | T9: 28.38 | U9: 47.22 | V9: =ABS(U9) -> 47.22 | W9: =IF(V9 <= _xlfn.PERCENTILE.INC($V$2:$V$633, 0.33), "Low", IF(V9 <= _xlfn.PERCENTILE.INC($V$2:$V$633, 0.67), "Medium", "High")) -> Low | X9: 0.194 | Y9: =IF(X9>30%,AVERAGEIF($X$2:$X$633,"<30%"),X9) -> 0.194 | Z9: =IF(Y9>0.2, "Yes", "No") -> No | AA9: 18 | AB9: =U9*AA9*(1-Y9) -> 685.06776 | AC9: =T9*AA9 -> 510.84 | AD9: =AB9-AC9 -> 174.22776 | AE9: =IF(AB9=0, 0, AD9 / AB9) -> 0.25432194 | AF9: =MIN(Y9,'Scenario Modeling'!$B$2) -> 0.194 | AG9: =ROUND(AA9 * (1 + 'Scenario Modeling'!$B$4), 0) -> 18 | AH9: =T9 * (1 + 'Scenario Modeling'!$B$3) -> 28.38 | AI9: =V9 * AG9 * (1 - AF9) -> 685.06776 | AJ9: =AI9 - (AH9 * AG9) -> 174.22776
A10: ORD-2024-589570 | B10: 45416 | C10: 45416 | D10: ="Q"&ROUNDUP(MONTH(B10)/3,0)&"-"&YEAR(B10) -> Q2-2024 | E10: 45441 | F10: 45441 | G10: =E10-B10 -> 25 | H10: =F10-B10 -> 25 | I10: =IF(H10<=7, "Yes", "No") -> No | J10: =_xlfn.MINIFS($B$2:$B$633, $L$2:$L$633, L10) -> 44941 | K10: Africa | L10: Nigeria | M10: Abuja | N10: =_xlfn.TEXTJOIN(" - ", TRUE, K10:M10) -> Africa - Nigeria - Abuja | O10: Non-Profit | P10: Marketplace | Q10: O. Wang | R10: Monitors | S10: MON-6892 | T10: 1295.34 | U10: 2530.81 | V10: =ABS(U10) -> 2530.81 | W10: =IF(V10 <= _xlfn.PERCENTILE.INC($V$2:$V$633, 0.33), "Low", IF(V10 <= _xlfn.PERCENTILE.INC($V$2:$V$633, 0.67), "Medium", "High")) -> High | X10: 0.031 | Y10: =IF(X10>30%,AVERAGEIF($X$2:$X$633,"<30%"),X10) -> 0.031 | Z10: =IF(Y10>0.2, "Yes", "No") -> No | AA10: 6 | AB10: =U10*AA10*(1-Y10) -> 14714.129 | AC10: =T10*AA10 -> 7772.04 | AD10: =AB10-AC10 -> 6942.0893 | AE10: =IF(AB10=0, 0, AD10 / AB10) -> 0.47179749 | AF10: =MIN(Y10,'Scenario Modeling'!$B$2) -> 0.031 | AG10: =ROUND(AA10 * (1 + 'Scenario Modeling'!$B$4), 0) -> 6 | AH10: =T10 * (1 + 'Scenario Modeling'!$B$3) -> 1295.34 | AI10: =V10 * AG10 * (1 - AF10) -> 14714.129 | AJ10: =AI10 - (AH10 * AG10) -> 6942.0893
A11: ORD-2025-997421 | B11: 45798 | C11: 45798 | D11: ="Q"&ROUNDUP(MONTH(B11)/3,0)&"-"&YEAR(B11) -> Q2-2025 | E11: 45817 | F11: 45817 | G11: =E11-B11 -> 19 | H11: =F11-B11 -> 19 | I11: =IF(H11<=7, "Yes", "No") -> No | J11: =_xlfn.MINIFS($B$2:$B$633, $L$2:$L$633, L11) -> 44955 | K11: Americas | L11: Brazil | M11: São Paulo | N11: =_xlfn.TEXTJOIN(" - ", TRUE, K11:M11) -> Americas - Brazil - São Paulo | O11: Non-Profit | P11: Online | Q11: A. Patel | R11: Components | S11: CMP-3731 | T11: 1331.38 | U11: 2309.56 | V11: =ABS(U11) -> 2309.56 | W11: =IF(V11 <= _xlfn.PERCENTILE.INC($V$2:$V$633, 0.33), "Low", IF(V11 <= _xlfn.PERCENTILE.INC($V$2:$V$633, 0.67), "Medium", "High")) -> High | X11: 0.149 | Y11: =IF(X11>30%,AVERAGEIF($X$2:$X$633,"<30%"),X11) -> 0.149 | Z11: =IF(Y11>0.2, "Yes", "No") -> No | AA11: 31 | AB11: =U11*AA11*(1-Y11) -> 60928.502 | AC11: =T11*AA11 -> 41272.78 | AD11: =AB11-AC11 -> 19655.722 | AE11: =IF(AB11=0, 0, AD11 / AB11) -> 0.32260308 | AF11: =MIN(Y11,'Scenario Modeling'!$B$2) -> 0.149 | AG11: =ROUND(AA11 * (1 + 'Scenario Modeling'!$B$4), 0) -> 31 | AH11: =T11 * (1 + 'Scenario Modeling'!$B$3) -> 1331.38 | AI11: =V11 * AG11 * (1 - AF11) -> 60928.502 | AJ11: =AI11 - (AH11 * AG11) -> 19655.722
A12: ORD-2024-210687 | B12: 45319 | C12: 45319 | D12: ="Q"&ROUNDUP(MONTH(B12)/3,0)&"-"&YEAR(B12) -> Q1-2024 | E12: 45331 | F12: 45331 | G12: =E12-B12 -> 12 | H12: =F12-B12 -> 12 | I12: =IF(H12<=7, "Yes", "No") -> No | J12: =_xlfn.MINIFS($B$2:$B$633, $L$2:$L$633, L12) -> 44948 | K12: Europe | L12: Germany | M12: Berlin | N12: =_xlfn.TEXTJOIN(" - ", TRUE, K12:M12) -> Europe - Germany - Berlin | O12: Corporate | P12: Online | Q12: G. Dubois | R12: Accessories | S12: ACC-7938 | T12: 644.17 | U12: 700.12 | V12: =ABS(U12) -> 700.12 | W12: =IF(V12 <= _xlfn.PERCENTILE.INC($V$2:$V$633, 0.33), "Low", IF(V12 <= _xlfn.PERCENTILE.INC($V$2:$V$633, 0.67), "Medium", "High")) -> Low | X12: 0.006 | Y12: =IF(X12>30%,AVERAGEIF($X$2:$X$633,"<30%"),X12) -> 0.006 | Z12: =IF(Y12>0.2, "Yes", "No") -> No | AA12: 23 | AB12: =U12*AA12*(1-Y12) -> 16006.143 | AC12: =T12*AA12 -> 14815.91 | AD12: =AB12-AC12 -> 1190.2334 | AE12: =IF(AB12=0, 0, AD12 / AB12) -> 0.074361038 | AF12: =MIN(Y12,'Scenario Modeling'!$B$2) -> 0.006 | AG12: =ROUND(AA12 * (1 + 'Scenario Modeling'!$B$4), 0) -> 23 | AH12: =T12 * (1 + 'Scenario Modeling'!$B$3) -> 644.17 | AI12: =V12 * AG12 * (1 - AF12) -> 16006.143 | AJ12: =AI12 - (AH12 * AG12) -> 1190.2334
A13: ORD-2025-515515 | B13: 45660 | C13: 45660 | D13: ="Q"&ROUNDUP(MONTH(B13)/3,0)&"-"&YEAR(B13) -> Q1-2025 | E13: 45680 | F13: 45680 | G13: =E13-B13 -> 20 | H13: =F13-B13 -> 20 | I13: =IF(H13<=7, "Yes", "No") -> No | J13: =_xlfn.MINIFS($B$2:$B$633, $L$2:$L$633, L13) -> 44988 | K13: Asia | L13: Japan | M13: Osaka | N13: =_xlfn.TEXTJOIN(" - ", TRUE, K13:M13) -> Asia - Japan - Osaka | O13: Corporate | P13: Distributor | Q13: F. Müller | R13: Phones | S13: PHN-7019 | T13: 908.6 | U13: 691.37 | V13: =ABS(U13) -> 691.37 | W13: =IF(V13 <= _xlfn.PERCENTILE.INC($V$2:$V$633, 0.33), "Low", IF(V13 <= _xlfn.PERCENTILE.INC($V$2:$V$633, 0.67), "Medium", "High")) -> Low | X13: 0.25 | Y13: =IF(X13>30%,AVERAGEIF($X$2:$X$633,"<30%"),X13) -> 0.25 | Z13: =IF(Y13>0.2, "Yes", "No") -> Yes | AA13: 20 | AB13: =U13*AA13*(1-Y13) -> 10370.55 | AC13: =T13*AA13 -> 18172 | AD13: =AB13-AC13 -> -7801.45 | AE13: =IF(AB13=0, 0, AD13 / AB13) -> -0.75226965 | AF13: =MIN(Y13,'Scenario Modeling'!$B$2) -> 0.25 | AG13: =ROUND(AA13 * (1 + 'Scenario Modeling'!$B$4), 0) -> 20 | AH13: =T13 * (1 + 'Scenario Modeling'!$B$3) -> 908.6 | AI13: =V13 * AG13 * (1 - AF13) -> 10370.55 | AJ13: =AI13 - (AH13 * AG13) -> -7801.45
A14: ORD-2025-487261 | B14: 45722 | C14: 45722 | D14: ="Q"&ROUNDUP(MONTH(B14)/3,0)&"-"&YEAR(B14) -> Q1-2025 | E14: 45747 | F14: 45747 | G14: =E14-B14 -> 25 | H14: =F14-B14 -> 25 | I14: =IF(H14<=7, "Yes", "No") -> No | J14: =_xlfn.MINIFS($B$2:$B$633, $L$2:$L$633, L14) -> 44955 | K14: Americas | L14: Brazil | M14: Brasília | N14: =_xlfn.TEXTJOIN(" - ", TRUE, K14:M14) -> Americas - Brazil - Brasília | O14: Non-Profit | P14: Online | Q14: J. Njeri | R14: Components | S14: CMP-3693 | T14: 331.57 | U14: 548.4 | V14: =ABS(U14) -> 548.4 | W14: =IF(V14 <= _xlfn.PERCENTILE.INC($V$2:$V$633, 0.33), "Low", IF(V14 <= _xlfn.PERCENTILE.INC($V$2:$V$633, 0.67), "Medium", "High")) -> Low | X14: 0.094 | Y14: =IF(X14>30%,AVERAGEIF($X$2:$X$633,"<30%"),X14) -> 0.094 | Z14: =IF(Y14>0.2, "Yes", "No") -> No | AA14: 10 | AB14: =U14*AA14*(1-Y14) -> 4968.504 | AC14: =T14*AA14 -> 3315.7 | AD14: =AB14-AC14 -> 1652.804 | AE14: =IF(AB14=0, 0, AD14 / AB14) -> 0.33265627 | AF14: =MIN(Y14,'Scenario Modeling'!$B$2) -> 0.094 | AG14: =ROUND(AA14 * (1 + 'Scenario Modeling'!$B$4), 0) -> 10 | AH14: =T14 * (1 + 'Scenario Modeling'!$B$3) -> 331.57 | AI14: =V14 * AG14 * (1 - AF14) -> 4968.504 | AJ14: =AI14 - (AH14 * AG14) -> 1652.804
A15: ORD-2024-890180 | B15: 45311 | C15: 45311 | D15: ="Q"&ROUNDUP(MONTH(B15)/3,0)&"-"&YEAR(B15) -> Q1-2024 | E15: 45335 | F15: 45335 | G15: =E15-B15 -> 24 | H15: =F15-B15 -> 24 | I15: =IF(H15<=7, "Yes", "No") -> No | J15: =_xlfn.MINIFS($B$2:$B$633, $L$2:$L$633, L15) -> 44936 | K15: Europe | L15: France | M15: Marseille | N15: =_xlfn.TEXTJOIN(" - ", TRUE, K15:M15) -> Europe - France - Marseille | O15: Corporate | P15: Retail | Q15: H. Kim | R15: Printers | S15: PRN-8392 | T15: 643.53 | U15: 1439.01 | V15: =ABS(U15) -> 1439.01 | W15: =IF(V15 <= _xlfn.PERCENTILE.INC($V$2:$V$633, 0.33), "Low", IF(V15 <= _xlfn.PERCENTILE.INC($V$2:$V$633, 0.67), "Medium", "High")) -> Medium | X15: 0 | Y15: =IF(X15>30%,AVERAGEIF($X$2:$X$633,"<30%"),X15) -> 0 | Z15: =IF(Y15>0.2, "Yes", "No") -> No | AA15: 15 | AB15: =U15*AA15*(1-Y15) -> 21585.15 | AC15: =T15*AA15 -> 9652.95 | AD15: =AB15-AC15 -> 11932.2 | AE15: =IF(AB15=0, 0, AD15 / AB15) -> 0.55279671 | AF15: =MIN(Y15,'Scenario Modeling'!$B$2) -> 0 | AG15: =ROUND(AA15 * (1 + 'Scenario Modeling'!$B$4), 0) -> 15 | AH15: =T15 * (1 + 'Scenario Modeling'!$B$3) -> 643.53 | AI15: =V15 * AG15 * (1 - AF15) -> 21585.15 | AJ15: =AI15 - (AH15 * AG15) -> 11932.2
A16: ORD-2025-840976 | B16: 45901 | C16: 45901 | D16: ="Q"&ROUNDUP(MONTH(B16)/3,0)&"-"&YEAR(B16) -> Q3-2025 | E16: 45930 | F16: 45930 | G16: =E16-B16 -> 29 | H16: =F16-B16 -> 29 | I16: =IF(H16<=7, "Yes", "No") -> No | J16: =_xlfn.MINIFS($B$2:$B$633, $L$2:$L$633, L16) -> 44955 | K16: Americas | L16: Brazil | M16: Brasília | N16: =_xlfn.TEXTJOIN(" - ", TRUE, K16:M16) -> Americas - Brazil - Brasília | O16: Education | P16: Retail | Q16: K. Singh | R16: Accessories | S16: ACC-1663 | T16: 780.59 | U16: 631.57 | V16: =ABS(U16) -> 631.57 | W16: =IF(V16 <= _xlfn.PERCENTILE.INC($V$2:$V$633, 0.33), "Low", IF(V16 <= _xlfn.PERCENTILE.INC($V$2:$V$633, 0.67), "Medium", "High")) -> Low | X16: 0 | Y16: =IF(X16>30%,AVERAGEIF($X$2:$X$633,"<30%"),X16) -> 0 | Z16: =IF(Y16>0.2, "Yes", "No") -> No | AA16: 12 | AB16: =U16*AA16*(1-Y16) -> 7578.84 | AC16: =T16*AA16 -> 9367.08 | AD16: =AB16-AC16 -> -1788.24 | AE16: =IF(AB16=0, 0, AD16 / AB16) -> -0.23595168 | AF16: =MIN(Y16,'Scenario Modeling'!$B$2) -> 0 | AG16: =ROUND(AA16 * (1 + 'Scenario Modeling'!$B$4), 0) -> 12 | AH16: =T16 * (1 + 'Scenario Modeling'!$B$3) -> 780.59 | AI16: =V16 * AG16 * (1 - AF16) -> 7578.84 | AJ16: =AI16 - (AH16 * AG16) -> -1788.24
A17: ORD-2023-937291 | B17: 45039 | C17: 45039 | D17: ="Q"&ROUNDUP(MONTH(B17)/3,0)&"-"&YEAR(B17) -> Q2-2023 | E17: 45038 | F17: =B17+11 -> 45050 | G17: =E17-B17 -> -1 | H17: =F17-B17 -> 11 | I17: =IF(H17<=7, "Yes", "No") -> No | J17: =_xlfn.MINIFS($B$2:$B$633, $L$2:$L$633, L17) -> 44946 | K17: Africa | L17: Kenya | M17: Nairobi | N17: =_xlfn.TEXTJOIN(" - ", TRUE, K17:M17) -> Africa - Kenya - Nairobi | O17: Small Business | P17: Direct | Q17: E. Garcia | R17: Laptops | S17: LAP-1698 | T17: 756.51 | U17: 850.8 | V17: =ABS(U17) -> 850.8 | W17: =IF(V17 <= _xlfn.PERCENTILE.INC($V$2:$V$633, 0.33), "Low", IF(V17 <= _xlfn.PERCENTILE.INC($V$2:$V$633, 0.67), "Medium", "High")) -> Medium | X17: 0.074 | Y17: =IF(X17>30%,AVERAGEIF($X$2:$X$633,"<30%"),X17) -> 0.074 | Z17: =IF(Y17>0.2, "Yes", "No") -> No | AA17: 9 | AB17: =U17*AA17*(1-Y17) -> 7090.5672 | AC17: =T17*AA17 -> 6808.59 | AD17: =AB17-AC17 -> 281.9772 | AE17: =IF(AB17=0, 0, AD17 / AB17) -> 0.039767933 | AF17: =MIN(Y17,'Scenario Modeling'!$B$2) -> 0.074 | AG17: =ROUND(AA17 * (1 + 'Scenario Modeling'!$B$4), 0) -> 9 | AH17: =T17 * (1 + 'Scenario Modeling'!$B$3) -> 756.51 | AI17: =V17 * AG17 * (1 - AF17) -> 7090.5672 | AJ17: =AI17 - (AH17 * AG17) -> 281.9772
A18: ORD-2024-206081 | B18: 45636 | C18: 45636 | D18: ="Q"&ROUNDUP(MONTH(B18)/3,0)&"-"&YEAR(B18) -> Q4-2024 | E18: 45665 | F18: 45665 | G18: =E18-B18 -> 29 | H18: =F18-B18 -> 29 | I18: =IF(H18<=7, "Yes", "No") -> No | J18: =_xlfn.MINIFS($B$2:$B$633, $L$2:$L$633, L18) -> 44936 | K18: Europe | L18: France | M18: Marseille | N18: =_xlfn.TEXTJOIN(" - ", TRUE, K18:M18) -> Europe - France - Marseille | O18: Small Business | P18: Retail | Q18: K. Singh | R18: Printers | S18: PRN-6791 | T18: 891.08 | U18: 1040.1 | V18: =ABS(U18) -> 1040.1 | W18: =IF(V18 <= _xlfn.PERCENTILE.INC($V$2:$V$633, 0.33), "Low", IF(V18 <= _xlfn.PERCENTILE.INC($V$2:$V$633, 0.67), "Medium", "High")) -> Medium | X18: 0.109 | Y18: =IF(X18>30%,AVERAGEIF($X$2:$X$633,"<30%"),X18) -> 0.109 | Z18: =IF(Y18>0.2, "Yes", "No") -> No | AA18: 28 | AB18: =U18*AA18*(1-Y18) -> 25948.415 | AC18: =T18*AA18 -> 24950.24 | AD18: =AB18-AC18 -> 998.1748 | AE18: =IF(AB18=0, 0, AD18 / AB18) -> 0.03846766 | AF18: =MIN(Y18,'Scenario Modeling'!$B$2) -> 0.109 | AG18: =ROUND(AA18 * (1 + 'Scenario Modeling'!$B$4), 0) -> 28 | AH18: =T18 * (1 + 'Scenario Modeling'!$B$3) -> 891.08 | AI18: =V18 * AG18 * (1 - AF18) -> 25948.415 | AJ18: =AI18 - (AH18 * AG18) -> 998.1748
A19: ORD-2025-233883 | B19: 45908 | C19: 45908 | D19: ="Q"&ROUNDUP(MONTH(B19)/3,0)&"-"&YEAR(B19) -> Q3-2025 | E19: 45916 | F19: 45916 | G19: =E19-B19 -> 8 | H19: =F19-B19 -> 8 | I19: =IF(H19<=7, "Yes", "No") -> No | J19: =_xlfn.MINIFS($B$2:$B$633, $L$2:$L$633, L19) -> 44988 | K19: Asia | L19: Japan | M19: Osaka | N19: =_xlfn.TEXTJOIN(" - ", TRUE, K19:M19) -> Asia - Japan - Osaka | O19: Corporate | P19: Distributor | Q19: C. Otieno | R19: Phones | S19: PHN-1197 | T19: 1225.57 | U19: 2705.57 | V19: =ABS(U19) -> 2705.57 | W19: =IF(V19 <= _xlfn.PERCENTILE.INC($V$2:$V$633, 0.33), "Low", IF(V19 <= _xlfn.PERCENTILE.INC($V$2:$V$633, 0.67), "Medium", "High")) -> High | X19: 0.183 | Y19: =IF(X19>30%,AVERAGEIF($X$2:$X$633,"<30%"),X19) -> 0.183 | Z19: =IF(Y19>0.2, "Yes", "No") -> No | AA19: 16 | AB19: =U19*AA19*(1-Y19) -> 35367.211 | AC19: =T19*AA19 -> 19609.12 | AD19: =AB19-AC19 -> 15758.091 | AE19: =IF(AB19=0, 0, AD19 / AB19) -> 0.44555651 | AF19: =MIN(Y19,'Scenario Modeling'!$B$2) -> 0.183 | AG19: =ROUND(AA19 * (1 + 'Scenario Modeling'!$B$4), 0) -> 16 | AH19: =T19 * (1 + 'Scenario Modeling'!$B$3) -> 1225.57 | AI19: =V19 * AG19 * (1 - AF19) -> 35367.211 | AJ19: =AI19 - (AH19 * AG19) -> 15758.091
A20: ORD-2025-843974 | B20: 45858 | C20: 45858 | D20: ="Q"&ROUNDUP(MONTH(B20)/3,0)&"-"&YEAR(B20) -> Q3-2025 | E20: 45874 | F20: 45874 | G20: =E20-B20 -> 16 | H20: =F20-B20 -> 16 | I20: =IF(H20<=7, "Yes", "No") -> No | J20: =_xlfn.MINIFS($B$2:$B$633, $L$2:$L$633, L20) -> 44955 | K20: Americas | L20: Brazil | M20: Brasília | N20: =_xlfn.TEXTJOIN(" - ", TRUE, K20:M20) -> Americas - Brazil - Brasília | O20: Enterprise | P20: Marketplace | Q20: G. Dubois | R20: Accessories | S20: ACC-8098 | T20: 1068.17 | U20: 2375.37 | V20: =ABS(U20) -> 2375.37 | W20: =IF(V20 <= _xlfn.PERCENTILE.INC($V$2:$V$633, 0.33), "Low", IF(V20 <= _xlfn.PERCENTILE.INC($V$2:$V$633, 0.67), "Medium", "High")) -> High | X20: 0.109 | Y20: =IF(X20>30%,AVERAGEIF($X$2:$X$633,"<30%"),X20) -> 0.109 | Z20: =IF(Y20>0.2, "Yes", "No") -> No | AA20: 18 | AB20: =U20*AA20*(1-Y20) -> 38096.184 | AC20: =T20*AA20 -> 19227.06 | AD20: =AB20-AC20 -> 18869.124 | AE20: =IF(AB20=0, 0, AD20 / AB20) -> 0.49530221 | AF20: =MIN(Y20,'Scenario Modeling'!$B$2) -> 0.109 | AG20: =ROUND(AA20 * (1 + 'Scenario Modeling'!$B$4), 0) -> 18 | AH20: =T20 * (1 + 'Scenario Modeling'!$B$3) -> 1068.17 | AI20: =V20 * AG20 * (1 - AF20) -> 38096.184 | AJ20: =AI20 - (AH20 * AG20) -> 18869.124
A21: ORD-2025-745263 | B21: 45798 | C21: 45798 | D21: ="Q"&ROUNDUP(MONTH(B21)/3,0)&"-"&YEAR(B21) -> Q2-2025 | E21: 45796 | F21: =B21+11 -> 45809 | G21: =E21-B21 -> -2 | H21: =F21-B21 -> 11 | I21: =IF(H21<=7, "Yes", "No") -> No | J21: =_xlfn.MINIFS($B$2:$B$633, $L$2:$L$633, L21) -> 44945 | K21: Europe | L21: United Kingdom | M21: Birmingham | N21: =_xlfn.TEXTJOIN(" - ", TRUE, K21:M21) -> Europe - United Kingdom - Birmingham | O21: Enterprise | P21: Online | Q21: M. Rossi | R21: Laptops | S21: LAP-3385 | T21: 1015.16 | U21: 2148.14 | V21: =ABS(U21) -> 2148.14 | W21: =IF(V21 <= _xlfn.PERCENTILE.INC($V$2:$V$633, 0.33), "Low", IF(V21 <= _xlfn.PERCENTILE.INC($V$2:$V$633, 0.67), "Medium", "High")) -> High | X21: 0.038 | Y21: =IF(X21>30%,AVERAGEIF($X$2:$X$633,"<30%"),X21) -> 0.038 | Z21: =IF(Y21>0.2, "Yes", "No") -> No | AA21: 19 | AB21: =U21*AA21*(1-Y21) -> 39263.703 | AC21: =T21*AA21 -> 19288.04 | AD21: =AB21-AC21 -> 19975.663 | AE21: =IF(AB21=0, 0, AD21 / AB21) -> 0.50875647 | AF21: =MIN(Y21,'Scenario Modeling'!$B$2) -> 0.038 | AG21: =ROUND(AA21 * (1 + 'Scenario Modeling'!$B$4), 0) -> 19 | AH21: =T21 * (1 + 'Scenario Modeling'!$B$3) -> 1015.16 | AI21: =V21 * AG21 * (1 - AF21) -> 39263.703 | AJ21: =AI21 - (AH21 * AG21) -> 19975.663
A22: ORD-2024-798002 | B22: 45498 | C22: 45498 | D22: ="Q"&ROUNDUP(MONTH(B22)/3,0)&"-"&YEAR(B22) -> Q3-2024 | E22: 45497 | F22: =B22+11 -> 45509 | G22: =E22-B22 -> -1 | H22: =F22-B22 -> 11 | I22: =IF(H22<=7, "Yes", "No") -> No | J22: =_xlfn.MINIFS($B$2:$B$633, $L$2:$L$633, L22) -> 44946 | K22: Africa | L22: Kenya | M22: Mombasa | N22: =_xlfn.TEXTJOIN(" - ", TRUE, K22:M22) -> Africa - Kenya - Mombasa | O22: Non-Profit | P22: Direct | Q22: J. Njeri | R22: Laptops | S22: LAP-9815 | T22: 1494.4 | U22: 3661.07 | V22: =ABS(U22) -> 3661.07 | W22: =IF(V22 <= _xlfn.PERCENTILE.INC($V$2:$V$633, 0.33), "Low", IF(V22 <= _xlfn.PERCENTILE.INC($V$2:$V$633, 0.67), "Medium", "High")) -> High | X22: 0.072 | Y22: =IF(X22>30%,AVERAGEIF($X$2:$X$633,"<30%"),X22) -> 0.072 | Z22: =IF(Y22>0.2, "Yes", "No") -> No | AA22: 7 | AB22: =U22*AA22*(1-Y22) -> 23782.311 | AC22: =T22*AA22 -> 10460.8 | AD22: =AB22-AC22 -> 13321.511 | AE22: =IF(AB22=0, 0, AD22 / AB22) -> 0.56014367 | AF22: =MIN(Y22,'Scenario Modeling'!$B$2) -> 0.072 | AG22: =ROUND(AA22 * (1 + 'Scenario Modeling'!$B$4), 0) -> 7 | AH22: =T22 * (1 + 'Scenario Modeling'!$B$3) -> 1494.4 | AI22: =V22 * AG22 * (1 - AF22) -> 23782.311 | AJ22: =AI22 - (AH22 * AG22) -> 13321.511
A23: ORD-2023-867836 | B23: 45057 | C23: 45057 | D23: ="Q"&ROUNDUP(MONTH(B23)/3,0)&"-"&YEAR(B23) -> Q2-2023 | E23: 45074 | F23: 45074 | G23: =E23-B23 -> 17 | H23: =F23-B23 -> 17 | I23: =IF(H23<=7, "Yes", "No") -> No | J23: =_xlfn.MINIFS($B$2:$B$633, $L$2:$L$633, L23) -> 44938 | K23: Asia | L23: China | M23: Shenzhen | N23: =_xlfn.TEXTJOIN(" - ", TRUE, K23:M23) -> Asia - China - Shenzhen | O23: Enterprise | P23: Marketplace | Q23: E. Garcia | R23: Networking | S23: NET-3255 | T23: 1331.19 | U23: 2903.09 | V23: =ABS(U23) -> 2903.09 | W23: =IF(V23 <= _xlfn.PERCENTILE.INC($V$2:$V$633, 0.33), "Low", IF(V23 <= _xlfn.PERCENTILE.INC($V$2:$V$633, 0.67), "Medium", "High")) -> High | X23: 0.143 | Y23: =IF(X23>30%,AVERAGEIF($X$2:$X$633,"<30%"),X23) -> 0.143 | Z23: =IF(Y23>0.2, "Yes", "No") -> No | AA23: 8 | AB23: =U23*AA23*(1-Y23) -> 19903.585 | AC23: =T23*AA23 -> 10649.52 | AD23: =AB23-AC23 -> 9254.065 | AE23: =IF(AB23=0, 0, AD23 / AB23) -> 0.46494463 | AF23: =MIN(Y23,'Scenario Modeling'!$B$2) -> 0.143 | AG23: =ROUND(AA23 * (1 + 'Scenario Modeling'!$B$4), 0) -> 8 | AH23: =T23 * (1 + 'Scenario Modeling'!$B$3) -> 1331.19 | AI23: =V23 * AG23 * (1 - AF23) -> 19903.585 | AJ23: =AI23 - (AH23 * AG23) -> 9254.065
A24: ORD-2025-580047 | B24: 45822 | C24: 45822 | D24: ="Q"&ROUNDUP(MONTH(B24)/3,0)&"-"&YEAR(B24) -> Q2-2025 | E24: 45837 | F24: 45837 | G24: =E24-B24 -> 15 | H24: =F24-B24 -> 15 | I24: =IF(H24<=7, "Yes", "No") -> No | J24: =_xlfn.MINIFS($B$2:$B$633, $L$2:$L$633, L24) -> 44941 | K24: Africa | L24: Nigeria | M24: Port Harcourt | N24: =_xlfn.TEXTJOIN(" - ", TRUE, K24:M24) -> Africa - Nigeria - Port Harcourt | O24: Consumer | P24: Marketplace | Q24: M. Rossi | R24: Accessories | S24: ACC-3961 | T24: 730.99 | U24: 1242.84 | V24: =ABS(U24) -> 1242.84 | W24: =IF(V24 <= _xlfn.PERCENTILE.INC($V$2:$V$633, 0.33), "Low", IF(V24 <= _xlfn.PERCENTILE.INC($V$2:$V$633, 0.67), "Medium", "High")) -> Medium | X24: 0.12 | Y24: =IF(X24>30%,AVERAGEIF($X$2:$X$633,"<30%"),X24) -> 0.12 | Z24: =IF(Y24>0.2, "Yes", "No") -> No | AA24: 10 | AB24: =U24*AA24*(1-Y24) -> 10936.992 | AC24: =T24*AA24 -> 7309.9 | AD24: =AB24-AC24 -> 3627.092 | AE24: =IF(AB24=0, 0, AD24 / AB24) -> 0.33163524 | AF24: =MIN(Y24,'Scenario Modeling'!$B$2) -> 0.12 | AG24: =ROUND(AA24 * (1 + 'Scenario Modeling'!$B$4), 0) -> 10 | AH24: =T24 * (1 + 'Scenario Modeling'!$B$3) -> 730.99 | AI24: =V24 * AG24 * (1 - AF24) -> 10936.992 | AJ24: =AI24 - (AH24 * AG24) -> 3627.092
A25: ORD-2024-500109 | B25: 45430 | C25: 45430 | D25: ="Q"&ROUNDUP(MONTH(B25)/3,0)&"-"&YEAR(B25) -> Q2-2024 | E25: 45435 | F25: 45435 | G25: =E25-B25 -> 5 | H25: =F25-B25 -> 5 | I25: =IF(H25<=7, "Yes", "No") -> Yes | J25: =_xlfn.MINIFS($B$2:$B$633, $L$2:$L$633, L25) -> 44939 | K25: Americas | L25: USA | M25: Chicago | N25: =_xlfn.TEXTJOIN(" - ", TRUE, K25:M25) -> Americas - USA - Chicago | O25: Enterprise | P25: Retail | Q25: H. Kim | R25: Laptops | S25: LAP-4987 | T25: 1274.59 | U25: 2553.69 | V25: =ABS(U25) -> 2553.69 | W25: =IF(V25 <= _xlfn.PERCENTILE.INC($V$2:$V$633, 0.33), "Low", IF(V25 <= _xlfn.PERCENTILE.INC($V$2:$V$633, 0.67), "Medium", "High")) -> High | X25: 0.01 | Y25: =IF(X25>30%,AVERAGEIF($X$2:$X$633,"<30%"),X25) -> 0.01 | Z25: =IF(Y25>0.2, "Yes", "No") -> No | AA25: 8 | AB25: =U25*AA25*(1-Y25) -> 20225.225 | AC25: =T25*AA25 -> 10196.72 | AD25: =AB25-AC25 -> 10028.505 | AE25: =IF(AB25=0, 0, AD25 / AB25) -> 0.49584145 | AF25: =MIN(Y25,'Scenario Modeling'!$B$2) -> 0.01 | AG25: =ROUND(AA25 * (1 + 'Scenario Modeling'!$B$4), 0) -> 8 | AH25: =T25 * (1 + 'Scenario Modeling'!$B$3) -> 1274.59 | AI25: =V25 * AG25 * (1 - AF25) -> 20225.225 | AJ25: =AI25 - (AH25 * AG25) -> 10028.505
A26: ORD-2023-271836 | B26: 44964 | C26: 44964 | D26: ="Q"&ROUNDUP(MONTH(B26)/3,0)&"-"&YEAR(B26) -> Q1-2023 | E26: 44969 | F26: 44969 | G26: =E26-B26 -> 5 | H26: =F26-B26 -> 5 | I26: =IF(H26<=7, "Yes", "No") -> Yes | J26: =_xlfn.MINIFS($B$2:$B$633, $L$2:$L$633, L26) -> 44955 | K26: Americas | L26: Brazil | M26: São Paulo | N26: =_xlfn.TEXTJOIN(" - ", TRUE, K26:M26) -> Americas - Brazil - São Paulo | O26: Education | P26: Online | Q26: N. Brown | R26: Components | S26: CMP-2693 | T26: 948.55 | U26: 2089.16 | V26: =ABS(U26) -> 2089.16 | W26: =IF(V26 <= _xlfn.PERCENTILE.INC($V$2:$V$633, 0.33), "Low", IF(V26 <= _xlfn.PERCENTILE.INC($V$2:$V$633, 0.67), "Medium", "High")) -> High | X26: 0.007 | Y26: =IF(X26>30%,AVERAGEIF($X$2:$X$633,"<30%"),X26) -> 0.007 | Z26: =IF(Y26>0.2, "Yes", "No") -> No | AA26: 12 | AB26: =U26*AA26*(1-Y26) -> 24894.431 | AC26: =T26*AA26 -> 11382.6 | AD26: =AB26-AC26 -> 13511.831 | AE26: =IF(AB26=0, 0, AD26 / AB26) -> 0.5427652 | AF26: =MIN(Y26,'Scenario Modeling'!$B$2) -> 0.007 | AG26: =ROUND(AA26 * (1 + 'Scenario Modeling'!$B$4), 0) -> 12 | AH26: =T26 * (1 + 'Scenario Modeling'!$B$3) -> 948.55 | AI26: =V26 * AG26 * (1 - AF26) -> 24894.431 | AJ26: =AI26 - (AH26 * AG26) -> 13511.831
A27: ORD-2024-215294 | B27: 45473 | C27: 45473 | D27: ="Q"&ROUNDUP(MONTH(B27)/3,0)&"-"&YEAR(B27) -> Q2-2024 | E27: 45487 | F27: 45487 | G27: =E27-B27 -> 14 | H27: =F27-B27 -> 14 | I27: =IF(H27<=7, "Yes", "No") -> No | J27: =_xlfn.MINIFS($B$2:$B$633, $L$2:$L$633, L27) -> 44955 | K27: Americas | L27: Brazil | M27: Brasília | N27: =_xlfn.TEXTJOIN(" - ", TRUE, K27:M27) -> Americas - Brazil - Brasília | O27: Education | P27: Retail | Q27: C. Otieno | R27: Accessories | S27: ACC-8683 | T27: 1491.85 | U27: 2583.02 | V27: =ABS(U27) -> 2583.02 | W27: =IF(V27 <= _xlfn.PERCENTILE.INC($V$2:$V$633, 0.33), "Low", IF(V27 <= _xlfn.PERCENTILE.INC($V$2:$V$633, 0.67), "Medium", "High")) -> High | X27: 0.168 | Y27: =IF(X27>30%,AVERAGEIF($X$2:$X$633,"<30%"),X27) -> 0.168 | Z27: =IF(Y27>0.2, "Yes", "No") -> No | AA27: 4 | AB27: =U27*AA27*(1-Y27) -> 8596.2906 | AC27: =T27*AA27 -> 5967.4 | AD27: =AB27-AC27 -> 2628.8906 | AE27: =IF(AB27=0, 0, AD27 / AB27) -> 0.30581686 | AF27: =MIN(Y27,'Scenario Modeling'!$B$2) -> 0.168 | AG27: =ROUND(AA27 * (1 + 'Scenario Modeling'!$B$4), 0) -> 4 | AH27: =T27 * (1 + 'Scenario Modeling'!$B$3) -> 1491.85 | AI27: =V27 * AG27 * (1 - AF27) -> 8596.2906 | AJ27: =AI27 - (AH27 * AG27) -> 2628.8906
A28: ORD-2024-788105 | B28: 45626 | C28: 45626 | D28: ="Q"&ROUNDUP(MONTH(B28)/3,0)&"-"&YEAR(B28) -> Q4-2024 | E28: 45656 | F28: 45656 | G28: =E28-B28 -> 30 | H28: =F28-B28 -> 30 | I28: =IF(H28<=7, "Yes", "No") -> No | J28: =_xlfn.MINIFS($B$2:$B$633, $L$2:$L$633, L28) -> 44936 | K28: Europe | L28: France | M28: Marseille | N28: =_xlfn.TEXTJOIN(" - ", TRUE, K28:M28) -> Europe - France - Marseille | O28: Consumer | P28: Marketplace | Q28: F. Müller | R28: Printers | S28: PRN-4170 | T28: 117.64 | U28: 175.67 | V28: =ABS(U28) -> 175.67 | W28: =IF(V28 <= _xlfn.PERCENTILE.INC($V$2:$V$633, 0.33), "Low", IF(V28 <= _xlfn.PERCENTILE.INC($V$2:$V$633, 0.67), "Medium", "High")) -> Low | X28: 0 | Y28: =IF(X28>30%,AVERAGEIF($X$2:$X$633,"<30%"),X28) -> 0 | Z28: =IF(Y28>0.2, "Yes", "No") -> No | AA28: 10 | AB28: =U28*AA28*(1-Y28) -> 1756.7 | AC28: =T28*AA28 -> 1176.4 | AD28: =AB28-AC28 -> 580.3 | AE28: =IF(AB28=0, 0, AD28 / AB28) -> 0.33033529 | AF28: =MIN(Y28,'Scenario Modeling'!$B$2) -> 0 | AG28: =ROUND(AA28 * (1 + 'Scenario Modeling'!$B$4), 0) -> 10 | AH28: =T28 * (1 + 'Scenario Modeling'!$B$3) -> 117.64 | AI28: =V28 * AG28 * (1 - AF28) -> 1756.7 | AJ28: =AI28 - (AH28 * AG28) -> 580.3
A29: ORD-2024-855073 | B29: 45492 | C29: 45492 | D29: ="Q"&ROUNDUP(MONTH(B29)/3,0)&"-"&YEAR(B29) -> Q3-2024 | E29: 45492 | F29: 45492 | G29: =E29-B29 -> 0 | H29: =F29-B29 -> 0 | I29: =IF(H29<=7, "Yes", "No") -> Yes | J29: =_xlfn.MINIFS($B$2:$B$633, $L$2:$L$633, L29) -> 44946 | K29: Africa | L29: Kenya | M29: Kisumu | N29: =_xlfn.TEXTJOIN(" - ", TRUE, K29:M29) -> Africa - Kenya - Kisumu | O29: Small Business | P29: Retail | Q29: A. Patel | R29: Phones | S29: PHN-6854 | T29: 857.24 | U29: 758.23 | V29: =ABS(U29) -> 758.23 | W29: =IF(V29 <= _xlfn.PERCENTILE.INC($V$2:$V$633, 0.33), "Low", IF(V29 <= _xlfn.PERCENTILE.INC($V$2:$V$633, 0.67), "Medium", "High")) -> Low | X29: 0.125 | Y29: =IF(X29>30%,AVERAGEIF($X$2:$X$633,"<30%"),X29) -> 0.125 | Z29: =IF(Y29>0.2, "Yes", "No") -> No | AA29: 6 | AB29: =U29*AA29*(1-Y29) -> 3980.7075 | AC29: =T29*AA29 -> 5143.44 | AD29: =AB29-AC29 -> -1162.7325 | AE29: =IF(AB29=0, 0, AD29 / AB29) -> -0.29209192 | AF29: =MIN(Y29,'Scenario Modeling'!$B$2) -> 0.125 | AG29: =ROUND(AA29 * (1 + 'Scenario Modeling'!$B$4), 0) -> 6 | AH29: =T29 * (1 + 'Scenario Modeling'!$B$3) -> 857.24 | AI29: =V29 * AG29 * (1 - AF29) -> 3980.7075 | AJ29: =AI29 - (AH29 * AG29) -> -1162.7325
A30: ORD-2023-897079 | B30: 45030 | C30: 45030 | D30: ="Q"&ROUNDUP(MONTH(B30)/3,0)&"-"&YEAR(B30) -> Q2-2023 | E30: 45060 | F30: 45060 | G30: =E30-B30 -> 30 | H30: =F30-B30 -> 30 | I30: =IF(H30<=7, "Yes", "No") -> No | J30: =_xlfn.MINIFS($B$2:$B$633, $L$2:$L$633, L30) -> 44946 | K30: Africa | L30: Kenya | M30: Nakuru | N30: =_xlfn.TEXTJOIN(" - ", TRUE, K30:M30) -> Africa - Kenya - Nakuru | O30: Consumer | P30: Marketplace | Q30: M. Rossi | R30: Phones | S30: PHN-1784 | T30: 209.25 | U30: 434.8 | V30: =ABS(U30) -> 434.8 | W30: =IF(V30 <= _xlfn.PERCENTILE.INC($V$2:$V$633, 0.33), "Low", IF(V30 <= _xlfn.PERCENTILE.INC($V$2:$V$633, 0.67), "Medium", "High")) -> Low | X30: 0 | Y30: =IF(X30>30%,AVERAGEIF($X$2:$X$633,"<30%"),X30) -> 0 | Z30: =IF(Y30>0.2, "Yes", "No") -> No | AA30: 9 | AB30: =U30*AA30*(1-Y30) -> 3913.2 | AC30: =T30*AA30 -> 1883.25 | AD30: =AB30-AC30 -> 2029.95 | AE30: =IF(AB30=0, 0, AD30 / AB30) -> 0.51874425 | AF30: =MIN(Y30,'Scenario Modeling'!$B$2) -> 0 | AG30: =ROUND(AA30 * (1 + 'Scenario Modeling'!$B$4), 0) -> 9 | AH30: =T30 * (1 + 'Scenario Modeling'!$B$3) -> 209.25 | AI30: =V30 * AG30 * (1 - AF30) -> 3913.2 | AJ30: =AI30 - (AH30 * AG30) -> 2029.95
A31: ORD-2025-548982 | B31: 45754 | C31: 45754 | D31: ="Q"&ROUNDUP(MONTH(B31)/3,0)&"-"&YEAR(B31) -> Q2-2025 | E31: 45758 | F31: 45758 | G31: =E31-B31 -> 4 | H31: =F31-B31 -> 4 | I31: =IF(H31<=7, "Yes", "No") -> Yes | J31: =_xlfn.MINIFS($B$2:$B$633, $L$2:$L$633, L31) -> 44936 | K31: Europe | L31: France | M31: Lyon | N31: =_xlfn.TEXTJOIN(" - ", TRUE, K31:M31) -> Europe - France - Lyon | O31: Education | P31: Retail | Q31: E. Garcia | R31: Networking | S31: NET-9716 | T31: 754.77 | U31: 1666.18 | V31: =ABS(U31) -> 1666.18 | W31: =IF(V31 <= _xlfn.PERCENTILE.INC($V$2:$V$633, 0.33), "Low", IF(V31 <= _xlfn.PERCENTILE.INC($V$2:$V$633, 0.67), "Medium", "High")) -> High | X31: 0.139 | Y31: =IF(X31>30%,AVERAGEIF($X$2:$X$633,"<30%"),X31) -> 0.139 | Z31: =IF(Y31>0.2, "Yes", "No") -> No | AA31: 14 | AB31: =U31*AA31*(1-Y31) -> 20084.134 | AC31: =T31*AA31 -> 10566.78 | AD31: =AB31-AC31 -> 9517.3537 | AE31: =IF(AB31=0, 0, AD31 / AB31) -> 0.47387425 | AF31: =MIN(Y31,'Scenario Modeling'!$B$2) -> 0.139 | AG31: =ROUND(AA31 * (1 + 'Scenario Modeling'!$B$4), 0) -> 14 | AH31: =T31 * (1 + 'Scenario Modeling'!$B$3) -> 754.77 | AI31: =V31 * AG31 * (1 - AF31) -> 20084.134 | AJ31: =AI31 - (AH31 * AG31) -> 9517.3537
A32: ORD-2024-170313 | B32: 45653 | C32: 45653 | D32: ="Q"&ROUNDUP(MONTH(B32)/3,0)&"-"&YEAR(B32) -> Q4-2024 | E32: 45672 | F32: 45672 | G32: =E32-B32 -> 19 | H32: =F32-B32 -> 19 | I32: =IF(H32<=7, "Yes", "No") -> No | J32: =_xlfn.MINIFS($B$2:$B$633, $L$2:$L$633, L32) -> 44955 | K32: Asia | L32: India | M32: Delhi | N32: =_xlfn.TEXTJOIN(" - ", TRUE, K32:M32) -> Asia - India - Delhi | O32: Non-Profit | P32: Distributor | Q32: G. Dubois | R32: Components | S32: CMP-6919 | T32: 495.59 | U32: 631.78 | V32: =ABS(U32) -> 631.78 | W32: =IF(V32 <= _xlfn.PERCENTILE.INC($V$2:$V$633, 0.33), "Low", IF(V32 <= _xlfn.PERCENTILE.INC($V$2:$V$633, 0.67), "Medium", "High")) -> Low | X32: 0.087 | Y32: =IF(X32>30%,AVERAGEIF($X$2:$X$633,"<30%"),X32) -> 0.087 | Z32: =IF(Y32>0.2, "Yes", "No") -> No | AA32: 17 | AB32: =U32*AA32*(1-Y32) -> 9805.8574 | AC32: =T32*AA32 -> 8425.03 | AD32: =AB32-AC32 -> 1380.8274 | AE32: =IF(AB32=0, 0, AD32 / AB32) -> 0.14081659 | AF32: =MIN(Y32,'Scenario Modeling'!$B$2) -> 0.087 | AG32: =ROUND(AA32 * (1 + 'Scenario Modeling'!$B$4), 0) -> 17 | AH32: =T32 * (1 + 'Scenario Modeling'!$B$3) -> 495.59 | AI32: =V32 * AG32 * (1 - AF32) -> 9805.8574 | AJ32: =AI32 - (AH32 * AG32) -> 1380.8274
A33: ORD-2023-562894 | B33: 44980 | C33: 44980 | D33: ="Q"&ROUNDUP(MONTH(B33)/3,0)&"-"&YEAR(B33) -> Q1-2023 | E33: 45010 | F33: 45010 | G33: =E33-B33 -> 30 | H33: =F33-B33 -> 30 | I33: =IF(H33<=7, "Yes", "No") -> No | J33: =_xlfn.MINIFS($B$2:$B$633, $L$2:$L$633, L33) -> 44928 | K33: Americas | L33: Canada | M33: Montreal | N33: =_xlfn.TEXTJOIN(" - ", TRUE, K33:M33) -> Americas - Canada - Montreal | O33: Enterprise | P33: Online | Q33: D. Smith | R33: Phones | S33: PHN-4854 | T33: 1242.66 | U33: 1794.07 | V33: =ABS(U33) -> 1794.07 | W33: =IF(V33 <= _xlfn.PERCENTILE.INC($V$2:$V$633, 0.33), "Low", IF(V33 <= _xlfn.PERCENTILE.INC($V$2:$V$633, 0.67), "Medium", "High")) -> High | X33: 0.089 | Y33: =IF(X33>30%,AVERAGEIF($X$2:$X$633,"<30%"),X33) -> 0.089 | Z33: =IF(Y33>0.2, "Yes", "No") -> No | AA33: 16 | AB33: =U33*AA33*(1-Y33) -> 26150.364 | AC33: =T33*AA33 -> 19882.56 | AD33: =AB33-AC33 -> 6267.8043 | AE33: =IF(AB33=0, 0, AD33 / AB33) -> 0.23968325 | AF33: =MIN(Y33,'Scenario Modeling'!$B$2) -> 0.089 | AG33: =ROUND(AA33 * (1 + 'Scenario Modeling'!$B$4), 0) -> 16 | AH33: =T33 * (1 + 'Scenario Modeling'!$B$3) -> 1242.66 | AI33: =V33 * AG33 * (1 - AF33) -> 26150.364 | AJ33: =AI33 - (AH33 * AG33) -> 6267.8043
A34: ORD-2025-474710 | B34: 45862 | C34: 45862 | D34: ="Q"&ROUNDUP(MONTH(B34)/3,0)&"-"&YEAR(B34) -> Q3-2025 | E34: 45875 | F34: 45875 | G34: =E34-B34 -> 13 | H34: =F34-B34 -> 13 | I34: =IF(H34<=7, "Yes", "No") -> No | J34: =_xlfn.MINIFS($B$2:$B$633, $L$2:$L$633, L34) -> 44933 | K34: Africa | L34: South Africa | M34: Johannesburg | N34: =_xlfn.TEXTJOIN(" - ", TRUE, K34:M34) -> Africa - South Africa - Johannesburg | O34: Education | P34: Marketplace | Q34: D. Smith | R34: Networking | S34: NET-7966 | T34: 1463.9 | U34: 2633.02 | V34: =ABS(U34) -> 2633.02 | W34: =IF(V34 <= _xlfn.PERCENTILE.INC($V$2:$V$633, 0.33), "Low", IF(V34 <= _xlfn.PERCENTILE.INC($V$2:$V$633, 0.67), "Medium", "High")) -> High | X34: 0.084 | Y34: =IF(X34>30%,AVERAGEIF($X$2:$X$633,"<30%"),X34) -> 0.084 | Z34: =IF(Y34>0.2, "Yes", "No") -> No | AA34: 4 | AB34: =U34*AA34*(1-Y34) -> 9647.3853 | AC34: =T34*AA34 -> 5855.6 | AD34: =AB34-AC34 -> 3791.7853 | AE34: =IF(AB34=0, 0, AD34 / AB34) -> 0.39303761 | AF34: =MIN(Y34,'Scenario Modeling'!$B$2) -> 0.084 | AG34: =ROUND(AA34 * (1 + 'Scenario Modeling'!$B$4), 0) -> 4 | AH34: =T34 * (1 + 'Scenario Modeling'!$B$3) -> 1463.9 | AI34: =V34 * AG34 * (1 - AF34) -> 9647.3853 | AJ34: =AI34 - (AH34 * AG34) -> 3791.7853
A35: ORD-2024-629525 | B35: 45400 | C35: 45400 | D35: ="Q"&ROUNDUP(MONTH(B35)/3,0)&"-"&YEAR(B35) -> Q2-2024 | E35: 45420 | F35: 45420 | G35: =E35-B35 -> 20 | H35: =F35-B35 -> 20 | I35: =IF(H35<=7, "Yes", "No") -> No | J35: =_xlfn.MINIFS($B$2:$B$633, $L$2:$L$633, L35) -> 44945 | K35: Europe | L35: United Kingdom | M35: London | N35: =_xlfn.TEXTJOIN(" - ", TRUE, K35:M35) -> Europe - United Kingdom - London | O35: Non-Profit | P35: Direct | Q35: D. Smith | R35: Laptops | S35: LAP-9932 | T35: 645.33 | U35: 1321.85 | V35: =ABS(U35) -> 1321.85 | W35: =IF(V35 <= _xlfn.PERCENTILE.INC($V$2:$V$633, 0.33), "Low", IF(V35 <= _xlfn.PERCENTILE.INC($V$2:$V$633, 0.67), "Medium", "High")) -> Medium | X35: 0 | Y35: =IF(X35>30%,AVERAGEIF($X$2:$X$633,"<30%"),X35) -> 0 | Z35: =IF(Y35>0.2, "Yes", "No") -> No | AA35: 10 | AB35: =U35*AA35*(1-Y35) -> 13218.5 | AC35: =T35*AA35 -> 6453.3 | AD35: =AB35-AC35 -> 6765.2 | AE35: =IF(AB35=0, 0, AD35 / AB35) -> 0.51179786 | AF35: =MIN(Y35,'Scenario Modeling'!$B$2) -> 0 | AG35: =ROUND(AA35 * (1 + 'Scenario Modeling'!$B$4), 0) -> 10 | AH35: =T35 * (1 + 'Scenario Modeling'!$B$3) -> 645.33 | AI35: =V35 * AG35 * (1 - AF35) -> 13218.5 | AJ35: =AI35 - (AH35 * AG35) -> 6765.2
A36: ORD-2024-167215 | B36: 45527 | C36: 45527 | D36: ="Q"&ROUNDUP(MONTH(B36)/3,0)&"-"&YEAR(B36) -> Q3-2024 | E36: 45525 | F36: =B36+13 -> 45540 | G36: =E36-B36 -> -2 | H36: =F36-B36 -> 13 | I36: =IF(H36<=7, "Yes", "No") -> No | J36: =_xlfn.MINIFS($B$2:$B$633, $L$2:$L$633, L36) -> 44933 | K36: Africa | L36: South Africa | M36: Johannesburg | N36: =_xlfn.TEXTJOIN(" - ", TRUE, K36:M36) -> Africa - South Africa - Johannesburg | O36: Education | P36: Retail | Q36: E. Garcia | R36: Components | S36: CMP-1559 | T36: 1432.52 | U36: 3036.87 | V36: =ABS(U36) -> 3036.87 | W36: =IF(V36 <= _xlfn.PERCENTILE.INC($V$2:$V$633, 0.33), "Low", IF(V36 <= _xlfn.PERCENTILE.INC($V$2:$V$633, 0.67), "Medium", "High")) -> High | X36: 0 | Y36: =IF(X36>30%,AVERAGEIF($X$2:$X$633,"<30%"),X36) -> 0 | Z36: =IF(Y36>0.2, "Yes", "No") -> No | AA36: 9 | AB36: =U36*AA36*(1-Y36) -> 27331.83 | AC36: =T36*AA36 -> 12892.68 | AD36: =AB36-AC36 -> 14439.15 | AE36: =IF(AB36=0, 0, AD36 / AB36) -> 0.52829064 | AF36: =MIN(Y36,'Scenario Modeling'!$B$2) -> 0 | AG36: =ROUND(AA36 * (1 + 'Scenario Modeling'!$B$4), 0) -> 9 | AH36: =T36 * (1 + 'Scenario Modeling'!$B$3) -> 1432.52 | AI36: =V36 * AG36 * (1 - AF36) -> 27331.83 | AJ36: =AI36 - (AH36 * AG36) -> 14439.15
A37: ORD-2023-864121 | B37: 45012 | C37: 45012 | D37: ="Q"&ROUNDUP(MONTH(B37)/3,0)&"-"&YEAR(B37) -> Q1-2023 | E37: 45038 | F37: 45038 | G37: =E37-B37 -> 26 | H37: =F37-B37 -> 26 | I37: =IF(H37<=7, "Yes", "No") -> No | J37: =_xlfn.MINIFS($B$2:$B$633, $L$2:$L$633, L37) -> 44955 | K37: Asia | L37: India | M37: Delhi | N37: =_xlfn.TEXTJOIN(" - ", TRUE, K37:M37) -> Asia - India - Delhi | O37: Non-Profit | P37: Marketplace | Q37: J. Njeri | R37: Printers | S37: PRN-4506 | T37: 178.53 | U37: 199.37 | V37: =ABS(U37) -> 199.37 | W37: =IF(V37 <= _xlfn.PERCENTILE.INC($V$2:$V$633, 0.33), "Low", IF(V37 <= _xlfn.PERCENTILE.INC($V$2:$V$633, 0.67), "Medium", "High")) -> Low | X37: 0.101 | Y37: =IF(X37>30%,AVERAGEIF($X$2:$X$633,"<30%"),X37) -> 0.101 | Z37: =IF(Y37>0.2, "Yes", "No") -> No | AA37: 37 | AB37: =U37*AA37*(1-Y37) -> 6631.6443 | AC37: =T37*AA37 -> 6605.61 | AD37: =AB37-AC37 -> 26.03431 | AE37: =IF(AB37=0, 0, AD37 / AB37) -> 0.00392577 | AF37: =MIN(Y37,'Scenario Modeling'!$B$2) -> 0.101 | AG37: =ROUND(AA37 * (1 + 'Scenario Modeling'!$B$4), 0) -> 37 | AH37: =T37 * (1 + 'Scenario Modeling'!$B$3) -> 178.53 | AI37: =V37 * AG37 * (1 - AF37) -> 6631.6443 | AJ37: =AI37 - (AH37 * AG37) -> 26.03431
A38: ORD-2024-692673 | B38: 45358 | C38: 45358 | D38: ="Q"&ROUNDUP(MONTH(B38)/3,0)&"-"&YEAR(B38) -> Q1-2024 | E38: 45376 | F38: 45376 | G38: =E38-B38 -> 18 | H38: =F38-B38 -> 18 | I38: =IF(H38<=7, "Yes", "No") -> No | J38: =_xlfn.MINIFS($B$2:$B$633, $L$2:$L$633, L38) -> 44948 | K38: Europe | L38: Germany | M38: Munich | N38: =_xlfn.TEXTJOIN(" - ", TRUE, K38:M38) -> Europe - Germany - Munich | O38: Corporate | P38: Online | Q38: B. Chen | R38: Components | S38: CMP-7617 | T38: 712.84 | U38: 927.51 | V38: =ABS(U38) -> 927.51 | W38: =IF(V38 <= _xlfn.PERCENTILE.INC($V$2:$V$633, 0.33), "Low", IF(V38 <= _xlfn.PERCENTILE.INC($V$2:$V$633, 0.67), "Medium", "High")) -> Medium | X38: 0.243 | Y38: =IF(X38>30%,AVERAGEIF($X$2:$X$633,"<30%"),X38) -> 0.243 | Z38: =IF(Y38>0.2, "Yes", "No") -> Yes | AA38: 27 | AB38: =U38*AA38*(1-Y38) -> 18957.377 | AC38: =T38*AA38 -> 19246.68 | AD38: =AB38-AC38 -> -289.30311 | AE38: =IF(AB38=0, 0, AD38 / AB38) -> -0.015260714 | AF38: =MIN(Y38,'Scenario Modeling'!$B$2) -> 0.243 | AG38: =ROUND(AA38 * (1 + 'Scenario Modeling'!$B$4), 0) -> 27 | AH38: =T38 * (1 + 'Scenario Modeling'!$B$3) -> 712.84 | AI38: =V38 * AG38 * (1 - AF38) -> 18957.377 | AJ38: =AI38 - (AH38 * AG38) -> -289.30311
A39: ORD-2025-718992 | B39: 45832 | C39: 45832 | D39: ="Q"&ROUNDUP(MONTH(B39)/3,0)&"-"&YEAR(B39) -> Q2-2025 | E39: 45848 | F39: 45848 | G39: =E39-B39 -> 16 | H39: =F39-B39 -> 16 | I39: =IF(H39<=7, "Yes", "No") -> No | J39: =_xlfn.MINIFS($B$2:$B$633, $L$2:$L$633, L39) -> 44938 | K39: Asia | L39: China | M39: Shanghai | N39: =_xlfn.TEXTJOIN(" - ", TRUE, K39:M39) -> Asia - China - Shanghai | O39: Enterprise | P39: Direct | Q39: N. Brown | R39: Components | S39: CMP-8390 | T39: 757.19 | U39: 1735.41 | V39: =ABS(U39) -> 1735.41 | W39: =IF(V39 <= _xlfn.PERCENTILE.INC($V$2:$V$633, 0.33), "Low", IF(V39 <= _xlfn.PERCENTILE.INC($V$2:$V$633, 0.67), "Medium", "High")) -> High | X39: 0.136 | Y39: =IF(X39>30%,AVERAGEIF($X$2:$X$633,"<30%"),X39) -> 0.136 | Z39: =IF(Y39>0.2, "Yes", "No") -> No | AA39: 8 | AB39: =U39*AA39*(1-Y39) -> 11995.154 | AC39: =T39*AA39 -> 6057.52 | AD39: =AB39-AC39 -> 5937.6339 | AE39: =IF(AB39=0, 0, AD39 / AB39) -> 0.49500273 | AF39: =MIN(Y39,'Scenario Modeling'!$B$2) -> 0.136 | AG39: =ROUND(AA39 * (1 + 'Scenario Modeling'!$B$4), 0) -> 8 | AH39: =T39 * (1 + 'Scenario Modeling'!$B$3) -> 757.19 | AI39: =V39 * AG39 * (1 - AF39) -> 11995.154 | AJ39: =AI39 - (AH39 * AG39) -> 5937.6339
A40: ORD-2024-599522 | B40: 45401 | C40: 45401 | D40: ="Q"&ROUNDUP(MONTH(B40)/3,0)&"-"&YEAR(B40) -> Q2-2024 | E40: 45418 | F40: 45418 | G40: =E40-B40 -> 17 | H40: =F40-B40 -> 17 | I40: =IF(H40<=7, "Yes", "No") -> No | J40: =_xlfn.MINIFS($B$2:$B$633, $L$2:$L$633, L40) -> 44941 | K40: Africa | L40: Nigeria | M40: Port Harcourt | N40: =_xlfn.TEXTJOIN(" - ", TRUE, K40:M40) -> Africa - Nigeria - Port Harcourt | O40: Non-Profit | P40: Online | Q40: A. Patel | R40: Printers | S40: PRN-7303 | T40: 865.33 | U40: 1395.64 | V40: =ABS(U40) -> 1395.64 | W40: =IF(V40 <= _xlfn.PERCENTILE.INC($V$2:$V$633, 0.33), "Low", IF(V40 <= _xlfn.PERCENTILE.INC($V$2:$V$633, 0.67), "Medium", "High")) -> Medium | X40: 0.175 | Y40: =IF(X40>30%,AVERAGEIF($X$2:$X$633,"<30%"),X40) -> 0.175 | Z40: =IF(Y40>0.2, "Yes", "No") -> No | AA40: 13 | AB40: =U40*AA40*(1-Y40) -> 14968.239 | AC40: =T40*AA40 -> 11249.29 | AD40: =AB40-AC40 -> 3718.949 | AE40: =IF(AB40=0, 0, AD40 / AB40) -> 0.24845601 | AF40: =MIN(Y40,'Scenario Modeling'!$B$2) -> 0.175 | AG40: =ROUND(AA40 * (1 + 'Scenario Modeling'!$B$4), 0) -> 13 | AH40: =T40 * (1 + 'Scenario Modeling'!$B$3) -> 865.33 | AI40: =V40 * AG40 * (1 - AF40) -> 14968.239 | AJ40: =AI40 - (AH40 * AG40) -> 3718.949
...

Sheet Brief
A1: Assignment
A2: Excel Mastery Assignment: Sales Operations & Analytics
A4: Overview:
A5: You are an analyst for a multi-regional electronics distributor. The 'Data' sheet contains 632 rows and 15 columns of transactional data with intentional data-quality issues.
A6: Your job is to clean, enrich, analyze, and present insights via a dynamic dashboard.
A8: Part A — Data Cleaning & Preparation:
A9: 1) Create a staging table where you:
A10: • Remove exact duplicate rows (define and document your duplicate criteria).
A11: • Fix data types (dates as Dates, numeric fields as numbers).
A12: • Handle missing values for City, Salesperson, and Channel using reasonable business logic (document your approach).
A13: • Flag and correct suspicious UnitPrice values (e.g., negative prices) and discounts (e.g., > 30%).
A14: • Ensure RequiredDate is not earlier than OrderDate; where it is, impute a corrected RequiredDate (explain your rule).
... A67: 15) Ensure your dashboard responds to slicers without broken references.

Sheet Dashboard

Sheet Dashboard Charts
A1: OrderDate (mmm-yyyy) | B1: (All)
A3: Row Labels | B3: Sum of GrossRevenue | E3: Sum of GrossProfit | F3: Column Labels
A4: 2023 | B4: 3723944.4 | E4: Row Labels | F4: Direct | G4: Distributor | H4: Marketplace | I4: Online | J4: Retail | K4: Grand Total | O4: Salesperson | P4: Average Discount
A5: Jan | B5: 178642.74 | E5: Africa | F5: 186715.22 | G5: 227456.27 | H5: 164839.3 | I5: 145453.95 | J5: 140531.64 | K5: 864996.38 | O5: A. Patel | P5: 0.1292003
A6: Feb | B6: 433149.2 | E6: Americas | F6: 258674.93 | G6: 177464.67 | H6: 97387.608 | I6: 261943.84 | J6: 69035.709 | K6: 864506.76 | O6: B. Chen | P6: 0.10938
A7: Mar | B7: 215576.67 | E7: Asia | F7: 233003.93 | G7: 155163.87 | H7: 151470.01 | I7: 149042.39 | J7: 169788.98 | K7: 858469.19 | O7: C. Otieno | P7: 0.12038456
A8: Apr | B8: 371604.58 | E8: Europe | F8: 300745.66 | G8: 105550.85 | H8: 111146.84 | I8: 200067.16 | J8: 150086.48 | K8: 867596.99 | O8: D. Smith | P8: 0.12628205
A9: May | B9: 471414.64 | E9: Grand Total | F9: 979139.74 | G9: 665635.66 | H9: 524843.76 | I9: 756507.34 | J9: 529442.81 | K9: 3455569.3 | O9: E. Garcia | P9: 0.10520588
A10: Jun | B10: 236474.06 | O10: F. Müller | P10: 0.10307547
A11: Jul | B11: 567977.52 | O11: G. Dubois | P11: 0.1172
A12: Aug | B12: 339044.67 | O12: H. Kim | P12: 0.12093842
A13: Sep | B13: 141266.51 | E13: Row Labels | F13: Sum of GrossRevenue | O13: I. Johnson | P13: 0.13473684
A14: Oct | B14: 259682.91 | E14: CMP-3938 | F14: 84136.12 | O14: J. Njeri | P14: 0.1172
A15: Nov | B15: 127009.51 | E15: CMP-8851 | F15: 139277.83 | O15: K. Singh | P15: 0.11825
A16: Dec | B16: 382101.37 | E16: LAP-3904 | F16: 82514.712 | O16: L. Okafor | P16: 0.12064379
A17: 2024 | B17: 4480268.4 | E17: LAP-8910 | F17: 102122.94 | O17: M. Rossi | P17: 0.1189105
A18: Jan | B18: 299100.37 | E18: MON-2266 | F18: 87404.93 | O18: N. Brown | P18: 0.11159375
A19: Feb | B19: 307793.71 | E19: MON-6699 | F19: 85637.74 | O19: O. Wang | P19: 0.12935135
A20: Mar | B20: 374300.11 | E20: MON-6962 | F20: 92715.25
A21: Apr | B21: 239506.83 | E21: NET-2365 | F21: 109244
A22: May | B22: 416985.77 | E22: NET-5523 | F22: 79548.756
A23: Jun | B23: 634490.72 | E23: NET-5987 | F23: 82141.34
A24: Jul | B24: 275628.62 | E24: Grand Total | F24: 944743.62
A25: Aug | B25: 389348.62
A26: Sep | B26: 347613.19
A27: Oct | B27: 425869.99
A28: Nov | B28: 416944.19
A29: Dec | B29: 352686.24
